<?xml version="1.0" ?>
<!-- =================================================================================== -->
<!-- |    This document was autogenerated by xacro from iiwa.urdf.xacro                | -->
<!-- |    EDITING THIS FILE BY HAND IS NOT RECOMMENDED                                 | -->
<!-- =================================================================================== -->
<robot name="iiwa">
  <material name="Black">
    <color rgba="0.0 0.0 0.0 1.0"/>
  </material>
  <material name="Blue">
    <color rgba="0.0 0.0 0.8 1.0"/>
  </material>
  <material name="Green">
    <color rgba="0.0 0.8 0.0 1.0"/>
  </material>
  <material name="Grey">
    <color rgba="0.4 0.4 0.4 1.0"/>
  </material>
  <material name="Orange">
    <color rgba="1.0 0.4235294117647059 0.0392156862745098 1.0"/>
  </material>
  <material name="Brown">
    <color rgba="0.8705882352941177 0.8117647058823529 0.7647058823529411 1.0"/>
  </material>
  <material name="Red">
    <color rgba="0.8 0.0 0.0 1.0"/>
  </material>
  <material name="White">
    <color rgba="1.0 1.0 1.0 1.0"/>
  </material>
  <material name="LightGrey">
    <color rgba="0.3 0.3 0.3 1.0"/>
  </material>
  <!-- Fix to world just for testing -->
  <link name="world"/>
  <!--joint between {parent} and link_0-->
  <joint name="world_F_base_joint" type="fixed">
    <origin rpy="0 0 0" xyz="0 0 0"/>
    <parent link="world"/>
    <child link="F_link_0"/>
  </joint>
  <link name="F_link_0">
    <inertial>
      <!--  Fixed -->
      <origin rpy="0 0 0" xyz="-0.1 0 0.07"/>
      <mass value="5"/>
      <inertia ixx="0.05" ixy="0" ixz="0" iyy="0.06" iyz="0" izz="0.03"/>
    </inertial>
    <visual>
      <origin rpy="0 0 0" xyz="0 0 0"/>
      <geometry>
        <mesh filename="../meshes/visual/link_0.stl"/>
      </geometry>
      <material name="Grey"/>
    </visual>
    <collision>
      <origin rpy="0 0 0" xyz="0 0 0"/>
      <geometry>
        <mesh filename="../meshes/collision/link_0.stl"/>
      </geometry>
      <material name="Grey"/>
    </collision>
    <self_collision_checking>
      <origin rpy="0 0 0" xyz="0 0 0"/>
      <geometry>
        <capsule length="0.25" radius="0.15"/>
      </geometry>
    </self_collision_checking>
  </link>
  <!-- joint between link_0 and link_1 -->
  <joint name="F_joint_1" type="revolute">
    <parent link="F_link_0"/>
    <child link="F_link_1"/>
    <origin rpy="0 0 0" xyz="0 0 0.1575"/>
    <axis xyz="0 0 1"/>
    <limit effort="320" lower="-2.9670597283903604" upper="2.9670597283903604" velocity="1.4835298641951802"/>
    <safety_controller k_position="100" k_velocity="10" soft_lower_limit="-2.9321531433504737" soft_upper_limit="2.9321531433504737"/>
    <!-- ETH
      <dynamics damping="0.24150"  friction="0.31909"/>
      -->
    <!-- Identified -->
    <dynamics damping="0.261257" friction="0.373279"/>
  </joint>
  <link name="F_link_1">
    <inertial>
      <!-- ETH
        <origin xyz="-0.003508 0.001602 -0.03139" rpy="0 0 0"/>
        <mass value="3.947808"/>
        <inertia ixx="0.004554"  ixy="0.00000"  ixz="-0.00000" iyy="0.00454" iyz="0.00001" izz="0.00029" />
        -->
      <!-- CAD -->
      <mass value="4.100238"/>
      <origin rpy="0 0 0" xyz="0.000004 -0.033790 0.122349"/>
      <inertia ixx="3.2869e-02" ixy="-4.3000e-07" ixz="9.4000e-07" iyy="3.3168e-02" iyz="4.8970e-03" izz="1.2274e-02"/>
      <!-- Identified Joint 1
		<mass value="5.006615"/>
		<origin value="0.000000 0.000000 0.000000" rpy="0.0 0.0 0.0"/>
		<inertia ixx="0.000212" ixy="0.000000" ixz="0.000000"
				 iyy="0.000212" iyz="0.000000" izz="0.000198"/>
				  -->
    </inertial>
    <visual>
      <origin rpy="0 0 0" xyz="0 0 0"/>
      <geometry>
        <mesh filename="../meshes/visual/link_1.stl"/>
      </geometry>
      <material name="Orange"/>
    </visual>
    <collision>
      <origin rpy="0 0 0" xyz="0 0 0"/>
      <geometry>
        <mesh filename="../meshes/collision/link_1.stl"/>
      </geometry>
      <material name="Orange"/>
    </collision>
  </link>
  <!-- joint between link_1 and link_2 -->
  <joint name="F_joint_2" type="revolute">
    <parent link="F_link_1"/>
    <child link="F_link_2"/>
    <origin rpy="1.5707963267948966   0 3.141592653589793" xyz="0 0 0.2025"/>
    <axis xyz="0 0 1"/>
    <limit effort="320" lower="-2.0943951023931953" upper="2.0943951023931953" velocity="1.4835298641951802"/>
    <safety_controller k_position="100" k_velocity="10" soft_lower_limit="-2.0594885173533086" soft_upper_limit="2.0594885173533086"/>
    <!-- ETH -->
    <dynamics damping="0.37328" friction="0.18130"/>
    <!-- Identified -->
    <dynamics damping="0.514832" friction="0.327121"/>
  </joint>
  <link name="F_link_2">
    <inertial>
      <!-- ETH
          <mass value="4.502752"/>
          <origin xyz="-0.007671 0.166693  -0.003551" rpy="0 0 0"/>
          <inertia ixx="0.00032"  ixy="0.00000"  ixz="0.000007" iyy="0.000100" iyz="-0.000003" izz="0.000419" />
        -->
      <!-- CAD -->
      <mass value="3.943457"/>
      <origin rpy="0 0 0" xyz="0.000285 0.058872 0.041961"/>
      <inertia ixx="3.0495e-02" ixy="-3.2800e-05" ixz="2.2370e-05" iyy="1.0969e-02" iyz="4.8615e-03" izz="3.0330e-02"/>
      <!-- Identified Joint 2
		<mass value="5.825137"/>
		<origin value="-0.034318 0.092214 0.017866" rpy="0.0 0.0 0.0"/>
		<inertia ixx="0.180428" ixy="-0.041335" ixz="-0.002909"
				 iyy="0.010668" iyz="-0.012488" izz="0.189084"/>
				  -->
    </inertial>
    <visual>
      <origin rpy="0 0 0" xyz="0 0 0"/>
      <geometry>
        <mesh filename="../meshes/visual/link_2.stl"/>
      </geometry>
      <material name="Orange"/>
    </visual>
    <collision>
      <origin rpy="0 0 0" xyz="0 0 0"/>
      <geometry>
        <mesh filename="../meshes/collision/link_2.stl"/>
      </geometry>
      <material name="Orange"/>
    </collision>
  </link>
  <!-- joint between link_2 and link_3 -->
  <joint name="F_joint_3" type="revolute">
    <parent link="F_link_2"/>
    <child link="F_link_3"/>
    <origin rpy="1.5707963267948966 0 3.141592653589793" xyz="0 0.2045 0"/>
    <axis xyz="0 0 1"/>
    <limit effort="176" lower="-2.9670597283903604" upper="2.9670597283903604" velocity="1.7453292519943295"/>
    <safety_controller k_position="100" k_velocity="10" soft_lower_limit="-2.9321531433504737" soft_upper_limit="2.9321531433504737"/>
    <!-- ETH
      <dynamics damping="0.11025"  friction="0.07302"/>
      -->
    <!-- Identified -->
    <dynamics damping="0.067733" friction="0.197613"/>
  </joint>
  <link name="F_link_3">
    <inertial>
      <!-- ETH
        <mass value="2.455197"/>
        <origin xyz="-0.002246 -0.034918 -0.02652" rpy="0 0 0"/>
        <inertia ixx="0.002233"  ixy="-0.000046"  ixz="0.000068" iyy="0.002191" iyz="0.000072" izz="0.000725" />
        -->
      <!-- CAD -->
      <mass value="4"/>
      <origin rpy="0 0 0" xyz="0.000002 0.029546 0.126448"/>
      <inertia ixx="3.1546e-02" ixy="-3.6628e-07" ixz="-3.9154e-07" iyy="2.9954e-02" iyz="-6.1227e-03" izz="9.5594e-03"/>
      <!-- Identified Joint 3
		<mass value="5.489953"/>
		<origin value="-0.002438 -0.001455 -0.036699" rpy="0.0 0.0 0.0"/>
		<inertia ixx="0.062734" ixy="0.000431" ixz="-0.003830"
				 iyy="0.062204" iyz="0.006941" izz="0.001225"/>
				 -->
    </inertial>
    <visual>
      <origin rpy="0 0 0" xyz="0 0 0"/>
      <geometry>
        <mesh filename="../meshes/visual/link_3.stl"/>
      </geometry>
      <material name="Orange"/>
    </visual>
    <collision>
      <origin rpy="0 0 0" xyz="0 0 0"/>
      <geometry>
        <mesh filename="../meshes/collision/link_3.stl"/>
      </geometry>
      <material name="Orange"/>
    </collision>
  </link>
  <!-- joint between link_3 and link_4 -->
  <joint name="F_joint_4" type="revolute">
    <parent link="F_link_3"/>
    <child link="F_link_4"/>
    <origin rpy="1.5707963267948966 0 0" xyz="0 0 0.2155"/>
    <axis xyz="0 0 1"/>
    <limit effort="176" lower="-2.0943951023931953" upper="2.0943951023931953" velocity="1.3089969389957472"/>
    <safety_controller k_position="100" k_velocity="10" soft_lower_limit="-2.0594885173533086" soft_upper_limit="2.0594885173533086"/>
    <!-- ETH
      <dynamics damping="0.10000"  friction="0.17671"/>
       -->
    <!-- Identified -->
    <dynamics damping="0.221950" friction="0.313484"/>
  </joint>
  <link name="F_link_4">
    <inertial>
      <!-- ETH
        <mass value="2.611550"/>
        <origin xyz="0.000196 -0.052679 0.038182" rpy="0 0 0"/>
        <inertia ixx="0.038444"  ixy="0.000880"  ixz="-0.001120" iyy="0.011437" iyz="-0.001113" izz=" 0.049880" />
        -->
      <!-- CAD -->
      <mass value="4"/>
      <origin rpy="0 0 0" xyz="-0.000000 0.067480 0.034254"/>
      <inertia ixx="2.5087e-02" ixy="-4.3896e-08" ixz="-1.3169e-07" iyy="8.9416e-03" iyz="4.1448e-03" izz="2.3916e-02"/>
      <!-- Identified Joint 4
		<mass value="3.549457"/>
		<origin value="-0.000693 0.080768 0.002979" rpy="0.0 0.0 0.0"/>
		<inertia ixx="0.007747" ixy="-0.000814" ixz="-0.003689"
				 iyy="0.018454" iyz="0.001719" izz="0.023215"/>
				 -->
    </inertial>
    <visual>
      <origin rpy="0 0 0" xyz="0 0 0"/>
      <geometry>
        <mesh filename="../meshes/visual/link_4.stl"/>
      </geometry>
      <material name="Orange"/>
    </visual>
    <collision>
      <origin rpy="0 0 0" xyz="0 0 0"/>
      <geometry>
        <mesh filename="../meshes/collision/link_4.stl"/>
      </geometry>
      <material name="Orange"/>
    </collision>
  </link>
  <!-- joint between link_4 and link_5 -->
  <joint name="F_joint_5" type="revolute">
    <parent link="F_link_4"/>
    <child link="F_link_5"/>
    <origin rpy="-1.5707963267948966 3.141592653589793 0" xyz="0 0.1845 0"/>
    <axis xyz="0 0 1"/>
    <limit effort="110" lower="-2.9670597283903604" upper="2.9670597283903604" velocity="2.2689280275926285"/>
    <safety_controller k_position="100" k_velocity="10" soft_lower_limit="-2.9321531433504737" soft_upper_limit="2.9321531433504737"/>
    <!-- ETH
      <dynamics damping="0.10000"  friction="0.03463"/>
        -->
    <!-- Identified -->
    <dynamics damping="0.072873" friction="0.528149"/>
  </joint>
  <link name="F_link_5">
    <inertial>
      <!-- ETH
        <mass value="3.410009"/>
        <origin xyz="0.000054  -0.002367 -0.21134" rpy="0 0 0"/>
        <inertia ixx="0.002769"  ixy="-0.000008"  ixz="0.000006" iyy="0.002842" iyz="-0.000001" izz="0.000117" />
        -->
      <!-- CAD -->
      <mass value="3.2"/>
      <origin rpy="0 0 0" xyz="0.000125 0.021388 0.075417"/>
      <inertia ixx="1.9009e-02" ixy="3.3348e-06" ixz="2.9559e-06" iyy="1.6414e-02" iyz="-5.8267e-03" izz="8.4231e-03"/>
      <!-- Identified Joint 5
		<mass value="3.049102"/>
		<origin value="-0.000921 0.004283 -0.034518" rpy="0.0 0.0 0.0"/>
		<inertia ixx="0.079024" ixy="-0.000029" ixz="-0.000428"
				 iyy="0.078664" iyz="-0.005315" izz="0.000564"/>
				  -->
    </inertial>
    <visual>
      <origin rpy="0 0 0" xyz="0 0 0"/>
      <geometry>
        <mesh filename="../meshes/visual/link_5.stl"/>
      </geometry>
      <material name="Orange"/>
    </visual>
    <collision>
      <origin rpy="0 0 0" xyz="0 0 0"/>
      <geometry>
        <mesh filename="../meshes/collision/link_5.stl"/>
      </geometry>
      <material name="Orange"/>
    </collision>
  </link>
  <!-- joint between link_5 and link_6 -->
  <joint name="F_joint_6" type="revolute">
    <parent link="F_link_5"/>
    <child link="F_link_6"/>
    <origin rpy="1.5707963267948966 0 0" xyz="0 0 0.2155"/>
    <axis xyz="0 0 1"/>
    <limit effort="40" lower="-2.0943951023931953" upper="2.0943951023931953" velocity="2.356194490192345"/>
    <safety_controller k_position="100" k_velocity="10" soft_lower_limit="-2.0594885173533086" soft_upper_limit="2.0594885173533086"/>
    <!-- ETH
      <dynamics damping="0.12484"  friction="0.13391"/>
        -->
    <!-- Identified -->
    <dynamics damping="0.008251" friction="0.211589"/>
  </joint>
  <link name="F_link_6">
    <inertial>
      <!-- ETH
        <mass value="3.387949"/>
        <origin xyz="0.000492  0.020190  -0.027496" rpy="0 0 0"/>
        <inertia ixx="0.000500"  ixy="-0.000050"  ixz="-0.000024" iyy="0.002809" iyz="-0.000041" izz="0.002315" />
        -->
      <!-- CAD -->
      <mass value="2.2"/>
      <origin rpy="0 0 0" xyz="-0.000000 0.002431 -0.001270"/>
      <inertia ixx="6.1583e-03" ixy="3.4928e-08" ixz="-1.9792e-07" iyy="4.4451e-03" iyz="3.2555e-04" izz="5.7995e-03"/>
      <!-- Identified Joint 6
		<mass value="3.290964"/>
		<origin value="0.001260 0.028869 -0.018748" rpy="0.0 0.0 0.0"/>
		<inertia ixx="0.001834" ixy="0.001071" ixz="-0.000003"
				 iyy="0.000903" iyz="0.000005" izz="0.002536"/>
				  -->
    </inertial>
    <visual>
      <origin rpy="0 0 0" xyz="0 0 0"/>
      <geometry>
        <mesh filename="../meshes/visual/link_6.stl"/>
      </geometry>
      <material name="Orange"/>
    </visual>
    <collision>
      <origin rpy="0 0 0" xyz="0 0 0"/>
      <geometry>
        <mesh filename="../meshes/collision/link_6.stl"/>
      </geometry>
      <material name="Orange"/>
    </collision>
  </link>
  <!-- joint between link_6 and link_7 -->
  <joint name="F_joint_7" type="revolute">
    <parent link="F_link_6"/>
    <child link="F_link_7"/>
    <origin rpy="-1.5707963267948966 3.141592653589793 0" xyz="0 0.081 0"/>
    <axis xyz="0 0 1"/>
    <limit effort="40" lower="-3.0543261909900763" upper="3.0543261909900763" velocity="2.356194490192345"/>
    <safety_controller k_position="100" k_velocity="10" soft_lower_limit="-3.01941960595019" soft_upper_limit="3.01941960595019"/>
    <!-- ETH
      <dynamics damping="0.10000"  friction="0.08710"/>
        -->
    <!-- Identified -->
    <dynamics damping="0.000999" friction="0.336998"/>
  </joint>
  <link name="F_link_7">
    <inertial>
      <!-- ETH
        <mass value="0.354321"/>
        <origin xyz="-0.034656 -0.023242 0.07138" rpy="0 0 0"/>
        <inertia ixx="0.007946"  ixy="0.000221"  ixz="-0.000294" iyy=" 0.010889" iyz="-0.000294" izz="0.002944" />
        -->
      <!-- CAD  -->
      <mass value="1.0"/>
      <origin rpy="0 0 0" xyz="0.000540 0.000569 0.026582"/>
      <inertia ixx="3.5211e-04" ixy="-1.4790e-07" ixz="4.7514e-06" iyy="3.5066e-04" iyz="-7.8574e-07" izz="4.3803e-04"/>
      <!-- Identified Joint 7
		<mass value="0.788067"/>
		<origin value="0.002935 0.001899 -0.029782" rpy="0.0 0.0 0.0"/>
		<inertia ixx="0.004431" ixy="0.000095" ixz="-0.001126"
				 iyy="0.004703" iyz="0.000355" izz="0.000533"/>
				  -->
    </inertial>
    <visual>
      <origin rpy="0 0 0" xyz="0 0 0"/>
      <geometry>
        <mesh filename="../meshes/visual/link_7.stl"/>
      </geometry>
      <material name="Grey"/>
    </visual>
    <collision>
      <origin rpy="0 0 0" xyz="0 0 0"/>
      <geometry>
        <mesh filename="../meshes/collision/link_7.stl"/>
      </geometry>
      <material name="Grey"/>
    </collision>
  </link>
  <joint name="F_joint_ee" type="fixed">
    <parent link="F_link_7"/>
    <child link="F_link_ee"/>
    <origin rpy="0 0 0" xyz="0 0 0.07"/>
  </joint>
  <link name="F_link_ee">
    <inertial>
      <origin rpy="0 0 0" xyz="0 0 0.0"/>
      <mass value="0.0"/>
      <inertia ixx="0.0" ixy="0.0" ixz="0.0" iyy="0.0" iyz="0.0" izz="0.0"/>
    </inertial>
  </link>
  <!-- Link0 -->
  <gazebo reference="F_link_0">
    <material>Gazebo/Grey</material>
    <mu1>0.2</mu1>
    <mu2>0.2</mu2>
    <selfCollide>0</selfCollide>
  </gazebo>
  <!-- Link1 -->
  <gazebo reference="F_link_1">
    <material>Gazebo/Orange</material>
    <mu1>0.2</mu1>
    <mu2>0.2</mu2>
    <selfCollide>0</selfCollide>
  </gazebo>
  <!-- Link2 -->
  <gazebo reference="F_link_2">
    <material>Gazebo/Orange</material>
    <mu1>0.2</mu1>
    <mu2>0.2</mu2>
    <selfCollide>0</selfCollide>
  </gazebo>
  <!-- Link3 -->
  <gazebo reference="F_link_3">
    <material>Gazebo/Orange</material>
    <mu1>0.2</mu1>
    <mu2>0.2</mu2>
    <selfCollide>0</selfCollide>
  </gazebo>
  <!-- Link4 -->
  <gazebo reference="F_link_4">
    <material>Gazebo/Orange</material>
    <mu1>0.2</mu1>
    <mu2>0.2</mu2>
    <selfCollide>0</selfCollide>
  </gazebo>
  <!-- Link5 -->
  <gazebo reference="F_link_5">
    <material>Gazebo/Orange</material>
    <mu1>0.2</mu1>
    <mu2>0.2</mu2>
    <selfCollide>0</selfCollide>
  </gazebo>
  <!-- Link6 -->
  <gazebo reference="F_link_6">
    <material>Gazebo/Orange</material>
    <mu1>0.2</mu1>
    <mu2>0.2</mu2>
    <selfCollide>0</selfCollide>
  </gazebo>
  <!-- Link7 -->
  <gazebo reference="F_link_7">
    <material>Gazebo/Grey</material>
    <mu1>0.2</mu1>
    <mu2>0.2</mu2>
    <selfCollide>0</selfCollide>
  </gazebo>
  <!-- Link7 -->
  <gazebo reference="F_joint_ee">
    <preserveFixedJoint>1</preserveFixedJoint>
  </gazebo>
  <transmission name="F_tran_1">
    <robotNamespace>/F</robotNamespace>
    <type>transmission_interface/SimpleTransmission</type>
    <joint name="F_joint_1">
      <hardwareInterface>PositionJointInterface</hardwareInterface>
    </joint>
    <actuator name="F_motor_1">
      <hardwareInterface>PositionJointInterface</hardwareInterface>
      <mechanicalReduction>1</mechanicalReduction>
    </actuator>
  </transmission>
  <transmission name="F_tran_2">
    <robotNamespace>/F</robotNamespace>
    <type>transmission_interface/SimpleTransmission</type>
    <joint name="F_joint_2">
      <hardwareInterface>PositionJointInterface</hardwareInterface>
    </joint>
    <actuator name="F_motor_2">
      <hardwareInterface>PositionJointInterface</hardwareInterface>
      <mechanicalReduction>1</mechanicalReduction>
    </actuator>
  </transmission>
  <transmission name="F_tran_3">
    <robotNamespace>/F</robotNamespace>
    <type>transmission_interface/SimpleTransmission</type>
    <joint name="F_joint_3">
      <hardwareInterface>PositionJointInterface</hardwareInterface>
    </joint>
    <actuator name="F_motor_3">
      <hardwareInterface>PositionJointInterface</hardwareInterface>
      <mechanicalReduction>1</mechanicalReduction>
    </actuator>
  </transmission>
  <transmission name="F_tran_4">
    <robotNamespace>/F</robotNamespace>
    <type>transmission_interface/SimpleTransmission</type>
    <joint name="F_joint_4">
      <hardwareInterface>PositionJointInterface</hardwareInterface>
    </joint>
    <actuator name="F_motor_4">
      <hardwareInterface>PositionJointInterface</hardwareInterface>
      <mechanicalReduction>1</mechanicalReduction>
    </actuator>
  </transmission>
  <transmission name="F_tran_5">
    <robotNamespace>/F</robotNamespace>
    <type>transmission_interface/SimpleTransmission</type>
    <joint name="F_joint_5">
      <hardwareInterface>PositionJointInterface</hardwareInterface>
    </joint>
    <actuator name="F_motor_5">
      <hardwareInterface>PositionJointInterface</hardwareInterface>
      <mechanicalReduction>1</mechanicalReduction>
    </actuator>
  </transmission>
  <transmission name="F_tran_6">
    <robotNamespace>/F</robotNamespace>
    <type>transmission_interface/SimpleTransmission</type>
    <joint name="F_joint_6">
      <hardwareInterface>PositionJointInterface</hardwareInterface>
    </joint>
    <actuator name="F_motor_6">
      <hardwareInterface>PositionJointInterface</hardwareInterface>
      <mechanicalReduction>1</mechanicalReduction>
    </actuator>
  </transmission>
  <transmission name="F_tran_7">
    <robotNamespace>/F</robotNamespace>
    <type>transmission_interface/SimpleTransmission</type>
    <joint name="F_joint_7">
      <hardwareInterface>PositionJointInterface</hardwareInterface>
    </joint>
    <actuator name="F_motor_7">
      <hardwareInterface>PositionJointInterface</hardwareInterface>
      <mechanicalReduction>1</mechanicalReduction>
    </actuator>
  </transmission>
  <gazebo>
    <plugin filename="libgazebo_ros_control.so" name="gazebo_ros_control">
      <robotSimType>iiwas_gazebo/GravityCompensationHWSim</robotSimType>
    </plugin>
  </gazebo>
</robot>

