<?xml version="1.0" ?>
<!-- =================================================================================== -->
<!-- |    This document was autogenerated by xacro from furuta_pendulum.xacro          | -->
<!-- |    EDITING THIS FILE BY HAND IS NOT RECOMMENDED                                 | -->
<!-- =================================================================================== -->
<robot name="FurutaPendulum" xmlns:xacro="http://www.ros.org/wiki/xacro">
  <material name="blue">
    <color rgba="0 0 0.9 1"/>
  </material>
  <material name="silver">
    <color rgba="0.75 0.75 0.75 1"/>
  </material>
  <material name="red">
    <color rgba="0.9 0 0 1"/>
  </material>
  <material name="black">
    <color rgba="0 0 0 1"/>
  </material>
  <link name="cube">
    <visual>
      <geometry>
        <box size="0.08 0.08 0.12"/>
      </geometry>
      <origin xyz="0 0 0"/>
      <material name="black"/>
    </visual>
    <inertial>
      <mass value="10.0"/>
      <inertia ixx="0.0173333333333" ixy="0.0" ixz="0.0" iyy="0.0173333333333" iyz="0.0" izz="0.0106666666667"/>
    </inertial>
  </link>
  <link name="arm">
    <visual>
      <geometry>
        <cylinder length="0.085" radius="0.0025"/>
      </geometry>
      <origin rpy="1.5708 0 0" xyz="0 0.0425 0"/>
      <material name="silver"/>
    </visual>
    <collision>
      <geometry>
        <cylinder length="0.085" radius="0.0025"/>
      </geometry>
      <origin rpy="1.5708 0 0" xyz="0 0.0425 0"/>
    </collision>
    <inertial>
      <mass value="0.095"/>
      <origin rpy="1.5708 0 0" xyz="0 0.0425 0"/>
      <inertia ixx="5.73463541667e-05" ixy="0.0" ixz="0.0" iyy="5.73463541667e-05" iyz="0.0" izz="2.96875e-07"/>
    </inertial>
  </link>
  <joint name="theta" type="revolute">
    <axis xyz="0 0 1"/>
    <limit effort="10000" lower="-2.356" upper="+2.356" velocity="1000"/>
    <dynamics damping="0.000005" friction="0.0"/>
    <origin rpy="0 0 0" xyz="0 0 0.08"/>
    <parent link="cube"/>
    <child link="arm"/>
  </joint>
  <link name="pole">
    <visual>
      <geometry>
        <cylinder length="0.129" radius="0.005"/>
      </geometry>
      <origin rpy="0 0 0" xyz="0 0 -0.06575"/>
      <material name="red"/>
    </visual>
    <inertial>
      <origin rpy="0 0 0" xyz="0 0 -0.0645"/>
      <mass value="0.024"/>
      <inertia ixx="3.3432e-05" ixy="0.0" ixz="0.0" iyy="3.3432e-05" iyz="0.0" izz="3e-07"/>
    </inertial>
    <collision>
      <geometry>
        <cylinder length="0.129" radius="0.005"/>
      </geometry>
      <origin rpy="0 0 0" xyz="0 0 -0.0645"/>
    </collision>
  </link>
  <joint name="arm_to_pole" type="continuous">
    <axis xyz="0 1 0"/>
    <dynamics damping="0.000001" friction="0.000"/>
    <origin rpy="0 0 0" xyz="0 0.085 0.0"/>
    <parent link="arm"/>
    <child link="pole"/>
  </joint>
</robot>

