<?xml version="1.0" ?>
<!-- =================================================================================== -->
<!-- |    This document was autogenerated by xacro from cartpole_short.xacro           | -->
<!-- |    EDITING THIS FILE BY HAND IS NOT RECOMMENDED                                 | -->
<!-- =================================================================================== -->
<robot name="CartpoleShort" xmlns:xacro="http://www.ros.org/wiki/xacro">
  <material name="blue">
    <color rgba="0 0 0.9 1"/>
  </material>
  <material name="red">
    <color rgba="1 0 0 1"/>
  </material>
  <material name="black">
    <color rgba="0 0 0 1"/>
  </material>
  <link name="slideBar">
    <visual>
      <geometry>
        <box size="0.8 0.01 0.01"/>
      </geometry>
      <origin xyz="0 0 0"/>
      <material name="gray">
        <color rgba="0 0 0 0.8"/>
      </material>
    </visual>
    <inertial>
      <mass value="10.0"/>
      <inertia ixx="0.000779" ixy="0.0" ixz="0.0" iyy="0.00068875" iyz="0.0" izz="0.00085975"/>
    </inertial>
  </link>
  <link name="cart">
    <visual>
      <geometry>
        <box size="0.09 0.1 0.1"/>
      </geometry>
      <origin xyz="0 0 0"/>
      <material name="black"/>
    </visual>
    <collision>
      <geometry>
        <box size="0.09 0.1 0.1"/>
      </geometry>
      <origin xyz="0 0 0"/>
    </collision>
    <inertial>
      <mass value="0.57"/>
      <inertia ixx="0.000779" ixy="0.0" ixz="0.0" iyy="0.00068875" iyz="0.0" izz="0.00085975"/>
    </inertial>
  </link>
  <joint name="slider_to_cart" type="prismatic">
    <axis xyz="1 0 0"/>
    <dynamics damping="0.0" friction="0.0"/>
    <origin xyz="0.0 0.0 0.0"/>
    <parent link="slideBar"/>
    <child link="cart"/>
    <limit effort="1000.0" lower="-10.4" upper="10.4" velocity="100"/>
  </joint>
  <link name="pole">
    <visual>
      <geometry>
        <cylinder length="0.3365" radius="0.005"/>
      </geometry>
      <origin rpy="0 0 0" xyz="0 0 -0.16825"/>
      <material name="red"/>
    </visual>
    <inertial>
      <origin rpy="0 0 0" xyz="0 0 -0.16825"/>
      <mass value="0.127"/>
      <inertia ixx="0.00119916839583" ixy="0.0" ixz="0.0" iyy="0.00119916839583" iyz="0.0" izz="1.5875e-06"/>
    </inertial>
    <collision>
      <geometry>
        <cylinder length="0.3365" radius="0.005"/>
      </geometry>
      <origin rpy="0 0 0" xyz="0 0 -0.16825"/>
    </collision>
  </link>
  <joint name="cart_to_pole" type="continuous">
    <axis xyz="0 1 0"/>
    <dynamics damping="0.0" friction="0.0"/>
    <origin rpy="0 0 0" xyz="0 0.06 0"/>
    <parent link="cart"/>
    <child link="pole"/>
  </joint>
</robot>

